#VRML_SIM R2022a utf8
WorldInfo {
  title "WalkingRobot"
}
Viewpoint {
  orientation 0.30414847424973784 0.340289770750464 -0.8897733293003074 1.5753033159072913
  position -0.2574579862189903 3.0147493368817915 2.288597849032449
}
TexturedBackgroundLight {
}
TexturedBackground {
}
Floor {
}
Robot {
  translation 0 0.0899998 0.29
  rotation 1 0 0 1.5708053071795867
  children [
    DEF Test Hinge2Joint {
      jointParameters HingeJointParameters {
      }
      device [
        RotationalMotor {
        }
      ]
      device2 [
        RotationalMotor {
        }
      ]
      endPoint DEF LeftLeg Solid {
        translation 0.2715429999999999 -0.07020319999999998 -5.212909999999997e-07
        rotation -0.12942905351200026 -0.9831054064615735 -0.12942905351200024 1.5878253071795863
        children [
          DEF LeftLegBody Shape {
            appearance PBRAppearance {
              metalness 0
            }
            geometry Capsule {
              height 0.2
              radius 0.05
            }
          }
        ]
        boundingObject USE LeftLegBody
        physics Physics {
        }
      }
    }
    Hinge2Joint {
      jointParameters HingeJointParameters {
      }
      device [
        RotationalMotor {
          name "RightLegtMotor1"
        }
      ]
      device2 [
        RotationalMotor {
          name "RightLegtMotor2"
        }
      ]
      endPoint DEF RightLeg Solid {
        translation -0.2715429999999998 -0.07020319999999995 -5.212909999999997e-07
        rotation 0.12943005351228426 -0.9831054064605905 0.12942805351145734 1.5878253071795863
        children [
          DEF RightLegBody Shape {
            appearance PBRAppearance {
              metalness 0
            }
            geometry Capsule {
              height 0.2
              radius 0.05
            }
          }
        ]
        name "solid(1)"
        boundingObject USE RightLegBody
        physics Physics {
        }
      }
    }
    Accelerometer {
    }
    DEF Body Shape {
      appearance PBRAppearance {
        baseColor 1 0.495445 0.138933
        metalness 0
      }
      geometry Capsule {
        height 0.3
        radius 0.14
      }
    }
  ]
  boundingObject USE Body
  physics Physics {
  }
  controller "WalkingBot"
}
