#VRML_SIM R2022a utf8
WorldInfo {
  title "WalkingRobot"
}
Viewpoint {
  orientation -0.13783503939070277 0.3000472889918323 0.9439137282002076 0.9058592197156529
  position -3.962344210400417 -5.054737038986698 2.5599293775628267
  follow "WalkBot"
  followSmoothness 0.2
}
TexturedBackgroundLight {
}
TexturedBackground {
}
Floor {
  size 10 100
}
Robot {
  translation 0 0 0.15
  rotation 1 0 0 1.5708053071795867
  children [
    GPS {
    }
    Hinge2Joint {
      jointParameters DEF LeftParam1 HingeJointParameters {
      }
      jointParameters2 DEF LeftParam2 JointParameters {
      }
      device [
        PositionSensor {
          name "LeftLegSensor1"
        }
        RotationalMotor {
          name "LeftLegMotor1"
        }
      ]
      device2 [
        PositionSensor {
          name "LeftLegSensor2"
        }
        RotationalMotor {
          name "LeftLegMotor2"
          acceleration 3
        }
      ]
      endPoint DEF LeftLeg Solid {
        translation 0.281202 -0.0727914000000001 -6.110420178244112e-07
        rotation 4.1001756358104254e-07 -0.9999999999996183 -7.715715640581736e-07 1.5707900000003818
        children [
          DEF LeftLegBody Shape {
            appearance PBRAppearance {
              metalness 0
            }
            geometry Capsule {
              height 0.2
              radius 0.05
            }
          }
        ]
        boundingObject USE LeftLegBody
        physics Physics {
        }
      }
    }
    Hinge2Joint {
      jointParameters DEF RightParam1 HingeJointParameters {
      }
      jointParameters2 DEF RightParam2 JointParameters {
      }
      device [
        PositionSensor {
          name "RightLegSensor1"
        }
        RotationalMotor {
          name "RightLegMotor1"
        }
      ]
      device2 [
        PositionSensor {
          name "RightLegSensor2"
        }
        RotationalMotor {
          name "RightLegMotor2"
        }
      ]
      endPoint DEF RightLeg Solid {
        translation -0.281202 -0.0727914 -4.34162e-07
        rotation 5.80171999999886e-07 -0.9999999999998035 -2.3779799999995328e-07 1.5707853071797828
        children [
          DEF RightLegBody Shape {
            appearance PBRAppearance {
              metalness 0
            }
            geometry Capsule {
              height 0.2
              radius 0.05
            }
          }
        ]
        name "solid(1)"
        boundingObject USE RightLegBody
        physics Physics {
        }
      }
    }
    Accelerometer {
      name "Accelerometer"
    }
    DEF Body Shape {
      appearance PBRAppearance {
        baseColor 1 0.495445 0.138933
        metalness 0
      }
      geometry Capsule {
        height 0.3
        radius 0.14
      }
    }
  ]
  name "WalkBot"
  boundingObject USE Body
  physics Physics {
  }
  controller "WalkingBot"
  supervisor TRUE
}
